Workbook

Sheet Eingaben
A1: 🏠 Immobilien Portfolio – Eingaben
A2: Alle Werte hier erfassen. Dashboard, Cashflow, Steuer & AfA sowie Verkauf berechnen sich automatisch.
A4: Globale Einstellungen (Steuer)
B5: Haushaltseinkommen p.a. (€) | D5: 0 | F5: Basis-ZvE (Haushalt, nach Kinderfreibetrag)
B6: Verheiratet? | D6: Nein | F6: =MAX(0,D5-D7*D8) -> 0
B7: Anzahl Kinder | D7: 0
B8: Kinderfreibetrag je Kind (€) | D8: 9756
B9: Pauschaler Steuersatz (ohne Haushaltseinkommen) | D9: 0.4
B10: Hinweis: gilt für alle Immobilien; jede Immobilie wird isoliert gegen dieses Haushaltseinkommen gerechnet (vereinfachte Modellrechnung).
A12: Immobilien
A13: Nr. | B13: Name | C13: Kaufjahr | D13: Aktueller Marktwert (€) | E13: Aktuelle Restschuld (€) | F13: Kaufpreis (€) | G13: Wohnfläche (m²) | H13: Mieteingabe | I13: Miete pro m² (€) | J13: Miete absolut (€/Monat) | K13: Mietsteigerung p.a. (%) | L13: Kaufnebenkosten (%) | M13: Nicht umlagef. Kosten p.a. (€) | N13: Eigenkapital gesamt (€) | O13: Sollzins p.a. (%) | P13: Tilgung p.a. (%) | Q13: Lineare AfA (%) | R13: Neubau | S13: Degressive AfA aktiv | T13: Degressive AfA (%) | U13: Sonder-AfA aktiv | V13: Sonder-AfA (%) | W13: Sonder-AfA Jahre | X13: Notizen | Z13: Kaufneben- kosten (€) | AA13: Gesamt- kosten (€) | AB13: Darlehen (€) | AC13: Mtl. Kalt- miete (€) | AD13: Gebäudewert / AfA-Basis (€) | AE13: Mtl. Annu- ität (€) | AF13: Zinssatz mtl. | AG13: Aktuelles Modelljahr
A14: 1 | B14: Musterwohnung Berlin | C14: 2024 | D14: 250000 | E14: 248000 | F14: 248000 | G14: 62 | H14: pro m² | I14: 12.42 | J14: 770 | K14: 0.02 | L14: 0.07 | M14: 1200 | N14: 17360 | O14: 0.042 | P14: 0.01 | Q14: 0.02 | R14: Nein | S14: Nein | T14: 0.05 | U14: Nein | V14: 0.05 | W14: 4 | X14: Beispielobjekt – bitte anpassen oder löschen | Z14: =IF($B14="","",F14*L14) -> 17360 | AA14: =IF($B14="","",F14+Z14) -> 265360 | AB14: =IF($B14="","",MAX(0,AA14-N14)) -> 248000 | AC14: =IF($B14="","",IF(H14="absolut",J14,G14*I14)) -> 770.04 | AD14: =IF($B14="","",F14*0.8) -> 198400 | AE14: =IF($B14="","",IF(AB14=0,0,AB14*(O14+P14)/12)) -> 1074.6667 | AF14: =IF($B14="","",O14/12) -> 0.0035 | AG14: =IF($B14="","",MIN(10,MAX(1,YEAR(TODAY())-C14+1))) -> 3
A15: 2 | Z15: =IF($B15="","",F15*L15) | AA15: =IF($B15="","",F15+Z15) | AB15: =IF($B15="","",MAX(0,AA15-N15)) | AC15: =IF($B15="","",IF(H15="absolut",J15,G15*I15)) | AD15: =IF($B15="","",F15*0.8) | AE15: =IF($B15="","",IF(AB15=0,0,AB15*(O15+P15)/12)) | AF15: =IF($B15="","",O15/12) | AG15: =IF($B15="","",MIN(10,MAX(1,YEAR(TODAY())-C15+1)))
A16: 3 | Z16: =IF($B16="","",F16*L16) | AA16: =IF($B16="","",F16+Z16) | AB16: =IF($B16="","",MAX(0,AA16-N16)) | AC16: =IF($B16="","",IF(H16="absolut",J16,G16*I16)) | AD16: =IF($B16="","",F16*0.8) | AE16: =IF($B16="","",IF(AB16=0,0,AB16*(O16+P16)/12)) | AF16: =IF($B16="","",O16/12) | AG16: =IF($B16="","",MIN(10,MAX(1,YEAR(TODAY())-C16+1)))
A17: 4 | Z17: =IF($B17="","",F17*L17) | AA17: =IF($B17="","",F17+Z17) | AB17: =IF($B17="","",MAX(0,AA17-N17)) | AC17: =IF($B17="","",IF(H17="absolut",J17,G17*I17)) | AD17: =IF($B17="","",F17*0.8) | AE17: =IF($B17="","",IF(AB17=0,0,AB17*(O17+P17)/12)) | AF17: =IF($B17="","",O17/12) | AG17: =IF($B17="","",MIN(10,MAX(1,YEAR(TODAY())-C17+1)))
A18: 5 | Z18: =IF($B18="","",F18*L18) | AA18: =IF($B18="","",F18+Z18) | AB18: =IF($B18="","",MAX(0,AA18-N18)) | AC18: =IF($B18="","",IF(H18="absolut",J18,G18*I18)) | AD18: =IF($B18="","",F18*0.8) | AE18: =IF($B18="","",IF(AB18=0,0,AB18*(O18+P18)/12)) | AF18: =IF($B18="","",O18/12) | AG18: =IF($B18="","",MIN(10,MAX(1,YEAR(TODAY())-C18+1)))
A19: 6 | Z19: =IF($B19="","",F19*L19) | AA19: =IF($B19="","",F19+Z19) | AB19: =IF($B19="","",MAX(0,AA19-N19)) | AC19: =IF($B19="","",IF(H19="absolut",J19,G19*I19)) | AD19: =IF($B19="","",F19*0.8) | AE19: =IF($B19="","",IF(AB19=0,0,AB19*(O19+P19)/12)) | AF19: =IF($B19="","",O19/12) | AG19: =IF($B19="","",MIN(10,MAX(1,YEAR(TODAY())-C19+1)))
A20: 7 | Z20: =IF($B20="","",F20*L20) | AA20: =IF($B20="","",F20+Z20) | AB20: =IF($B20="","",MAX(0,AA20-N20)) | AC20: =IF($B20="","",IF(H20="absolut",J20,G20*I20)) | AD20: =IF($B20="","",F20*0.8) | AE20: =IF($B20="","",IF(AB20=0,0,AB20*(O20+P20)/12)) | AF20: =IF($B20="","",O20/12) | AG20: =IF($B20="","",MIN(10,MAX(1,YEAR(TODAY())-C20+1)))
A21: 8 | Z21: =IF($B21="","",F21*L21) | AA21: =IF($B21="","",F21+Z21) | AB21: =IF($B21="","",MAX(0,AA21-N21)) | AC21: =IF($B21="","",IF(H21="absolut",J21,G21*I21)) | AD21: =IF($B21="","",F21*0.8) | AE21: =IF($B21="","",IF(AB21=0,0,AB21*(O21+P21)/12)) | AF21: =IF($B21="","",O21/12) | AG21: =IF($B21="","",MIN(10,MAX(1,YEAR(TODAY())-C21+1)))
A22: 9 | Z22: =IF($B22="","",F22*L22) | AA22: =IF($B22="","",F22+Z22) | AB22: =IF($B22="","",MAX(0,AA22-N22)) | AC22: =IF($B22="","",IF(H22="absolut",J22,G22*I22)) | AD22: =IF($B22="","",F22*0.8) | AE22: =IF($B22="","",IF(AB22=0,0,AB22*(O22+P22)/12)) | AF22: =IF($B22="","",O22/12) | AG22: =IF($B22="","",MIN(10,MAX(1,YEAR(TODAY())-C22+1)))
A23: 10 | Z23: =IF($B23="","",F23*L23) | AA23: =IF($B23="","",F23+Z23) | AB23: =IF($B23="","",MAX(0,AA23-N23)) | AC23: =IF($B23="","",IF(H23="absolut",J23,G23*I23)) | AD23: =IF($B23="","",F23*0.8) | AE23: =IF($B23="","",IF(AB23=0,0,AB23*(O23+P23)/12)) | AF23: =IF($B23="","",O23/12) | AG23: =IF($B23="","",MIN(10,MAX(1,YEAR(TODAY())-C23+1)))

Sheet Dashboard
A1: 📊 Dashboard – Portfolio-Übersicht
A2: Aggregierte Kennzahlen und Diagramme über alle Immobilien. Aktualisiert sich automatisch aus 'Eingaben'.
B4: Gesamtwert | E4: Gesamtrestschuld | H4: Nettovermögen | K4: Anzahl Immobilien
B5: =SUM($C$46:$C$55) -> 250000 | E5: =SUM($D$46:$D$55) -> 248000 | H5: =SUM($C$46:$C$55)-SUM($D$46:$D$55) -> 2000 | K5: =COUNTIF($B$46:$B$55,"?*") -> 1
B7: Mieteinnahmen p.a. | E7: Ausgaben p.a. | H7: Cashflow p.a. | K7: Ø Bruttorendite
B8: =SUM($G$46:$G$55) -> 9613.7954 | E8: =SUM($H$46:$H$55) -> 14096 | H8: =SUM($I$46:$I$55) -> -2681.9029 | K8: =IFERROR(SUM($G$46:$G$55)/SUM($C$46:$C$55),0) -> 0.038455182
A11: Diagramme
A12: Diagramme aktualisieren sich automatisch, sobald weitere Immobilien in 'Eingaben' erfasst werden.
A44: Berechnungstabelle (Basis für KPIs & Diagramme)
A45: Nr. | B45: Immobilie | C45: Wert (€) | D45: Restschuld (€) | E45: Eigenkapital (€) | F45: Modelljahr | G45: Miete p.a. (€) | H45: Ausgaben p.a. (€) | I45: Cashflow p.a. (€) | J45: Bruttorendite | K45: Beste IRR | L45: CF positiv (€) | M45: CF negativ (€)
A46: 1 | B46: =IF(Eingaben!$B$14="","",Eingaben!$B$14) -> Musterwohnung Berlin | C46: =IF(Eingaben!$B$14="",0,Eingaben!$D$14) -> 250000 | D46: =IF(Eingaben!$B$14="",0,Eingaben!$E$14) -> 248000 | E46: =C46-D46 -> 2000 | F46: =IF(Eingaben!$B$14="","",Eingaben!$AG$14) -> 3 | G46: =IF(Eingaben!$B$14="",0,INDEX(Cashflow!$E$5:$E$104,(A46-1)*10+F46)) -> 9613.7954 | H46: =IF(Eingaben!$B$14="",0,INDEX(Cashflow!$I$5:$I$104,(A46-1)*10+F46)+INDEX(Cashflow!$K$5:$K$104,(A46-1)*10+F46)) -> 14096 | I46: =IF(Eingaben!$B$14="",0,INDEX(Cashflow!$M$5:$M$104,(A46-1)*10+F46)) -> -2681.9029 | J46: =IF(OR(Eingaben!$B$14="",C46=0),0,G46/C46) -> 0.038455182 | K46: =IF(Eingaben!$B$14="",0,_xlfn.MAXIFS(Verkauf!$J$5:$J$34,Verkauf!$A$5:$A$34,A46)) -> 0.098674431 | L46: =IF(I46>=0,I46,0) -> 0 | M46: =IF(I46<0,I46,0) -> -2681.9029
A47: 2 | B47: =IF(Eingaben!$B$15="","",Eingaben!$B$15) | C47: =IF(Eingaben!$B$15="",0,Eingaben!$D$15) -> 0 | D47: =IF(Eingaben!$B$15="",0,Eingaben!$E$15) -> 0 | E47: =C47-D47 -> 0 | F47: =IF(Eingaben!$B$15="","",Eingaben!$AG$15) | G47: =IF(Eingaben!$B$15="",0,INDEX(Cashflow!$E$5:$E$104,(A47-1)*10+F47)) -> 0 | H47: =IF(Eingaben!$B$15="",0,INDEX(Cashflow!$I$5:$I$104,(A47-1)*10+F47)+INDEX(Cashflow!$K$5:$K$104,(A47-1)*10+F47)) -> 0 | I47: =IF(Eingaben!$B$15="",0,INDEX(Cashflow!$M$5:$M$104,(A47-1)*10+F47)) -> 0 | J47: =IF(OR(Eingaben!$B$15="",C47=0),0,G47/C47) -> 0 | K47: =IF(Eingaben!$B$15="",0,_xlfn.MAXIFS(Verkauf!$J$5:$J$34,Verkauf!$A$5:$A$34,A47)) -> 0 | L47: =IF(I47>=0,I47,0) -> 0 | M47: =IF(I47<0,I47,0) -> 0
A48: 3 | B48: =IF(Eingaben!$B$16="","",Eingaben!$B$16) | C48: =IF(Eingaben!$B$16="",0,Eingaben!$D$16) -> 0 | D48: =IF(Eingaben!$B$16="",0,Eingaben!$E$16) -> 0 | E48: =C48-D48 -> 0 | F48: =IF(Eingaben!$B$16="","",Eingaben!$AG$16) | G48: =IF(Eingaben!$B$16="",0,INDEX(Cashflow!$E$5:$E$104,(A48-1)*10+F48)) -> 0 | H48: =IF(Eingaben!$B$16="",0,INDEX(Cashflow!$I$5:$I$104,(A48-1)*10+F48)+INDEX(Cashflow!$K$5:$K$104,(A48-1)*10+F48)) -> 0 | I48: =IF(Eingaben!$B$16="",0,INDEX(Cashflow!$M$5:$M$104,(A48-1)*10+F48)) -> 0 | J48: =IF(OR(Eingaben!$B$16="",C48=0),0,G48/C48) -> 0 | K48: =IF(Eingaben!$B$16="",0,_xlfn.MAXIFS(Verkauf!$J$5:$J$34,Verkauf!$A$5:$A$34,A48)) -> 0 | L48: =IF(I48>=0,I48,0) -> 0 | M48: =IF(I48<0,I48,0) -> 0
A49: 4 | B49: =IF(Eingaben!$B$17="","",Eingaben!$B$17) | C49: =IF(Eingaben!$B$17="",0,Eingaben!$D$17) -> 0 | D49: =IF(Eingaben!$B$17="",0,Eingaben!$E$17) -> 0 | E49: =C49-D49 -> 0 | F49: =IF(Eingaben!$B$17="","",Eingaben!$AG$17) | G49: =IF(Eingaben!$B$17="",0,INDEX(Cashflow!$E$5:$E$104,(A49-1)*10+F49)) -> 0 | H49: =IF(Eingaben!$B$17="",0,INDEX(Cashflow!$I$5:$I$104,(A49-1)*10+F49)+INDEX(Cashflow!$K$5:$K$104,(A49-1)*10+F49)) -> 0 | I49: =IF(Eingaben!$B$17="",0,INDEX(Cashflow!$M$5:$M$104,(A49-1)*10+F49)) -> 0 | J49: =IF(OR(Eingaben!$B$17="",C49=0),0,G49/C49) -> 0 | K49: =IF(Eingaben!$B$17="",0,_xlfn.MAXIFS(Verkauf!$J$5:$J$34,Verkauf!$A$5:$A$34,A49)) -> 0 | L49: =IF(I49>=0,I49,0) -> 0 | M49: =IF(I49<0,I49,0) -> 0
A50: 5 | B50: =IF(Eingaben!$B$18="","",Eingaben!$B$18) | C50: =IF(Eingaben!$B$18="",0,Eingaben!$D$18) -> 0 | D50: =IF(Eingaben!$B$18="",0,Eingaben!$E$18) -> 0 | E50: =C50-D50 -> 0 | F50: =IF(Eingaben!$B$18="","",Eingaben!$AG$18) | G50: =IF(Eingaben!$B$18="",0,INDEX(Cashflow!$E$5:$E$104,(A50-1)*10+F50)) -> 0 | H50: =IF(Eingaben!$B$18="",0,INDEX(Cashflow!$I$5:$I$104,(A50-1)*10+F50)+INDEX(Cashflow!$K$5:$K$104,(A50-1)*10+F50)) -> 0 | I50: =IF(Eingaben!$B$18="",0,INDEX(Cashflow!$M$5:$M$104,(A50-1)*10+F50)) -> 0 | J50: =IF(OR(Eingaben!$B$18="",C50=0),0,G50/C50) -> 0 | K50: =IF(Eingaben!$B$18="",0,_xlfn.MAXIFS(Verkauf!$J$5:$J$34,Verkauf!$A$5:$A$34,A50)) -> 0 | L50: =IF(I50>=0,I50,0) -> 0 | M50: =IF(I50<0,I50,0) -> 0
A51: Modellgrenzen: vereinfachte Modellrechnung, keine Steuer-, Rechts- oder Anlageberatung. 'Wert' und 'Restschuld' sind manuell in 'Eingaben' zu pflegen (tatsächliche aktuelle Werte); alle übrigen Kennzahlen basieren auf den Modellannahmen (Kaufpreis, Zins, Miete, AfA etc.).
A53: 8 | B53: =IF(Eingaben!$B$21="","",Eingaben!$B$21) | C53: =IF(Eingaben!$B$21="",0,Eingaben!$D$21) -> 0 | D53: =IF(Eingaben!$B$21="",0,Eingaben!$E$21) -> 0 | E53: =C53-D53 -> 0 | F53: =IF(Eingaben!$B$21="","",Eingaben!$AG$21) | G53: =IF(Eingaben!$B$21="",0,INDEX(Cashflow!$E$5:$E$104,(A53-1)*10+F53)) -> 0 | H53: =IF(Eingaben!$B$21="",0,INDEX(Cashflow!$I$5:$I$104,(A53-1)*10+F53)+INDEX(Cashflow!$K$5:$K$104,(A53-1)*10+F53)) -> 0 | I53: =IF(Eingaben!$B$21="",0,INDEX(Cashflow!$M$5:$M$104,(A53-1)*10+F53)) -> 0 | J53: =IF(OR(Eingaben!$B$21="",C53=0),0,G53/C53) -> 0 | K53: =IF(Eingaben!$B$21="",0,_xlfn.MAXIFS(Verkauf!$J$5:$J$34,Verkauf!$A$5:$A$34,A53)) -> 0 | L53: =IF(I53>=0,I53,0) -> 0 | M53: =IF(I53<0,I53,0) -> 0
A54: 9 | B54: =IF(Eingaben!$B$22="","",Eingaben!$B$22) | C54: =IF(Eingaben!$B$22="",0,Eingaben!$D$22) -> 0 | D54: =IF(Eingaben!$B$22="",0,Eingaben!$E$22) -> 0 | E54: =C54-D54 -> 0 | F54: =IF(Eingaben!$B$22="","",Eingaben!$AG$22) | G54: =IF(Eingaben!$B$22="",0,INDEX(Cashflow!$E$5:$E$104,(A54-1)*10+F54)) -> 0 | H54: =IF(Eingaben!$B$22="",0,INDEX(Cashflow!$I$5:$I$104,(A54-1)*10+F54)+INDEX(Cashflow!$K$5:$K$104,(A54-1)*10+F54)) -> 0 | I54: =IF(Eingaben!$B$22="",0,INDEX(Cashflow!$M$5:$M$104,(A54-1)*10+F54)) -> 0 | J54: =IF(OR(Eingaben!$B$22="",C54=0),0,G54/C54) -> 0 | K54: =IF(Eingaben!$B$22="",0,_xlfn.MAXIFS(Verkauf!$J$5:$J$34,Verkauf!$A$5:$A$34,A54)) -> 0 | L54: =IF(I54>=0,I54,0) -> 0 | M54: =IF(I54<0,I54,0) -> 0
A55: 10 | B55: =IF(Eingaben!$B$23="","",Eingaben!$B$23) | C55: =IF(Eingaben!$B$23="",0,Eingaben!$D$23) -> 0 | D55: =IF(Eingaben!$B$23="",0,Eingaben!$E$23) -> 0 | E55: =C55-D55 -> 0 | F55: =IF(Eingaben!$B$23="","",Eingaben!$AG$23) | G55: =IF(Eingaben!$B$23="",0,INDEX(Cashflow!$E$5:$E$104,(A55-1)*10+F55)) -> 0 | H55: =IF(Eingaben!$B$23="",0,INDEX(Cashflow!$I$5:$I$104,(A55-1)*10+F55)+INDEX(Cashflow!$K$5:$K$104,(A55-1)*10+F55)) -> 0 | I55: =IF(Eingaben!$B$23="",0,INDEX(Cashflow!$M$5:$M$104,(A55-1)*10+F55)) -> 0 | J55: =IF(OR(Eingaben!$B$23="",C55=0),0,G55/C55) -> 0 | K55: =IF(Eingaben!$B$23="",0,_xlfn.MAXIFS(Verkauf!$J$5:$J$34,Verkauf!$A$5:$A$34,A55)) -> 0 | L55: =IF(I55>=0,I55,0) -> 0 | M55: =IF(I55<0,I55,0) -> 0

Sheet Cashflow
A1: 📈 Cashflow – 10-Jahres-Verlauf je Immobilie
A2: Ein Block pro Immobilie (Jahr 1–10). Werte werden automatisch aus 'Eingaben' und 'Steuer & AfA' berechnet.
A4: Nr. | B4: Immobilie | C4: Jahr | D4: Restschuld Jahresanfang (€) | E4: Miete p.a. (€) | F4: Miete mtl. (€) | G4: Zinsen p.a. (€) | H4: Tilgung p.a. (€) | I4: Bankrate p.a. (€) | J4: Restschuld Jahresende (€) | K4: Nicht umlagef. Kosten (€) | L4: Steuerwirkung (€) | M4: Cashflow p.a. (€) | N4: Cashflow mtl. (€) | O4: Zinssatz mtl. (Lookup) | P4: Annuität mtl. (Lookup)
A5: 1 | B5: =IF(Eingaben!$B$14="","",Eingaben!$B$14) -> Musterwohnung Berlin | C5: 1 | D5: =IF(Eingaben!$B$14="","",Eingaben!$AB$14) -> 248000 | E5: =IF(Eingaben!$B$14="","",Eingaben!$AC$14*12*(1+Eingaben!$K$14)^(1-1)) -> 9240.48 | F5: =IF(Eingaben!$B$14="","",E5/12) -> 770.04 | G5: =IF(Eingaben!$B$14="","",I5-H5) -> 10367.699 | H5: =IF(Eingaben!$B$14="","",D5-J5) -> 2528.3014 | I5: =IF(Eingaben!$B$14="","",P5*12) -> 12896 | J5: =IF(Eingaben!$B$14="","",IF(O5=0,MAX(0,D5-P5*12),MAX(0,D5*(1+O5)^12-P5*((1+O5)^12-1)/O5))) -> 245471.7 | K5: =IF(Eingaben!$B$14="","",Eingaben!$M$14) -> 1200 | L5: =IF(Eingaben!$B$14="","",'Steuer & AfA'!L5) -> 2038.0874 | M5: =IF(Eingaben!$B$14="","",E5+L5-I5-K5) -> -2817.4326 | N5: =IF(Eingaben!$B$14="","",M5/12) -> -234.78605 | O5: =IF(Eingaben!$B$14="","",Eingaben!$AF$14) -> 0.0035 | P5: =IF(Eingaben!$B$14="","",Eingaben!$AE$14) -> 1074.6667
A6: 1 | B6: =IF(Eingaben!$B$14="","",Eingaben!$B$14) -> Musterwohnung Berlin | C6: 2 | D6: =IF(Eingaben!$B$14="","",J5) -> 245471.7 | E6: =IF(Eingaben!$B$14="","",Eingaben!$AC$14*12*(1+Eingaben!$K$14)^(2-1)) -> 9425.2896 | F6: =IF(Eingaben!$B$14="","",E6/12) -> 785.4408 | G6: =IF(Eingaben!$B$14="","",I6-H6) -> 10259.442 | H6: =IF(Eingaben!$B$14="","",D6-J6) -> 2636.5582 | I6: =IF(Eingaben!$B$14="","",P6*12) -> 12896 | J6: =IF(Eingaben!$B$14="","",IF(O6=0,MAX(0,D6-P6*12),MAX(0,D6*(1+O6)^12-P6*((1+O6)^12-1)/O6))) -> 242835.14 | K6: =IF(Eingaben!$B$14="","",Eingaben!$M$14) -> 1200 | L6: =IF(Eingaben!$B$14="","",'Steuer & AfA'!L6) -> 1920.8609 | M6: =IF(Eingaben!$B$14="","",E6+L6-I6-K6) -> -2749.8495 | N6: =IF(Eingaben!$B$14="","",M6/12) -> -229.15413 | O6: =IF(Eingaben!$B$14="","",Eingaben!$AF$14) -> 0.0035 | P6: =IF(Eingaben!$B$14="","",Eingaben!$AE$14) -> 1074.6667
A7: 1 | B7: =IF(Eingaben!$B$14="","",Eingaben!$B$14) -> Musterwohnung Berlin | C7: 3 | D7: =IF(Eingaben!$B$14="","",J6) -> 242835.14 | E7: =IF(Eingaben!$B$14="","",Eingaben!$AC$14*12*(1+Eingaben!$K$14)^(3-1)) -> 9613.7954 | F7: =IF(Eingaben!$B$14="","",E7/12) -> 801.14962 | G7: =IF(Eingaben!$B$14="","",I7-H7) -> 10146.55 | H7: =IF(Eingaben!$B$14="","",D7-J7) -> 2749.4504 | I7: =IF(Eingaben!$B$14="","",P7*12) -> 12896 | J7: =IF(Eingaben!$B$14="","",IF(O7=0,MAX(0,D7-P7*12),MAX(0,D7*(1+O7)^12-P7*((1+O7)^12-1)/O7))) -> 240085.69 | K7: =IF(Eingaben!$B$14="","",Eingaben!$M$14) -> 1200 | L7: =IF(Eingaben!$B$14="","",'Steuer & AfA'!L7) -> 1800.3017 | M7: =IF(Eingaben!$B$14="","",E7+L7-I7-K7) -> -2681.9029 | N7: =IF(Eingaben!$B$14="","",M7/12) -> -223.49191 | O7: =IF(Eingaben!$B$14="","",Eingaben!$AF$14) -> 0.0035 | P7: =IF(Eingaben!$B$14="","",Eingaben!$AE$14) -> 1074.6667
A8: 1 | B8: =IF(Eingaben!$B$14="","",Eingaben!$B$14) -> Musterwohnung Berlin | C8: 4 | D8: =IF(Eingaben!$B$14="","",J7) -> 240085.69 | E8: =IF(Eingaben!$B$14="","",Eingaben!$AC$14*12*(1+Eingaben!$K$14)^(4-1)) -> 9806.0713 | F8: =IF(Eingaben!$B$14="","",E8/12) -> 817.17261 | G8: =IF(Eingaben!$B$14="","",I8-H8) -> 10028.824 | H8: =IF(Eingaben!$B$14="","",D8-J8) -> 2867.1764 | I8: =IF(Eingaben!$B$14="","",P8*12) -> 12896 | J8: =IF(Eingaben!$B$14="","",IF(O8=0,MAX(0,D8-P8*12),MAX(0,D8*(1+O8)^12-P8*((1+O8)^12-1)/O8))) -> 237218.51 | K8: =IF(Eingaben!$B$14="","",Eingaben!$M$14) -> 1200 | L8: =IF(Eingaben!$B$14="","",'Steuer & AfA'!L8) -> 1676.3009 | M8: =IF(Eingaben!$B$14="","",E8+L8-I8-K8) -> -2613.6278 | N8: =IF(Eingaben!$B$14="","",M8/12) -> -217.80231 | O8: =IF(Eingaben!$B$14="","",Eingaben!$AF$14) -> 0.0035 | P8: =IF(Eingaben!$B$14="","",Eingaben!$AE$14) -> 1074.6667
A9: 1 | B9: =IF(Eingaben!$B$14="","",Eingaben!$B$14) -> Musterwohnung Berlin | C9: 5 | D9: =IF(Eingaben!$B$14="","",J8) -> 237218.51 | E9: =IF(Eingaben!$B$14="","",Eingaben!$AC$14*12*(1+Eingaben!$K$14)^(5-1)) -> 10002.193 | F9: =IF(Eingaben!$B$14="","",E9/12) -> 833.51606 | G9: =IF(Eingaben!$B$14="","",I9-H9) -> 9906.0569 | H9: =IF(Eingaben!$B$14="","",D9-J9) -> 2989.9431 | I9: =IF(Eingaben!$B$14="","",P9*12) -> 12896 | J9: =IF(Eingaben!$B$14="","",IF(O9=0,MAX(0,D9-P9*12),MAX(0,D9*(1+O9)^12-P9*((1+O9)^12-1)/O9))) -> 234228.57 | K9: =IF(Eingaben!$B$14="","",Eingaben!$M$14) -> 1200 | L9: =IF(Eingaben!$B$14="","",'Steuer & AfA'!L9) -> 1548.7457 | M9: =IF(Eingaben!$B$14="","",E9+L9-I9-K9) -> -2545.0616 | N9: =IF(Eingaben!$B$14="","",M9/12) -> -212.08847 | O9: =IF(Eingaben!$B$14="","",Eingaben!$AF$14) -> 0.0035 | P9: =IF(Eingaben!$B$14="","",Eingaben!$AE$14) -> 1074.6667
A10: 1 | B10: =IF(Eingaben!$B$14="","",Eingaben!$B$14) -> Musterwohnung Berlin | C10: 6 | D10: =IF(Eingaben!$B$14="","",J9) -> 234228.57 | E10: =IF(Eingaben!$B$14="","",Eingaben!$AC$14*12*(1+Eingaben!$K$14)^(6-1)) -> 10202.237 | F10: =IF(Eingaben!$B$14="","",E10/12) -> 850.18638 | G10: =IF(Eingaben!$B$14="","",I10-H10) -> 9778.0335 | H10: =IF(Eingaben!$B$14="","",D10-J10) -> 3117.9665 | I10: =IF(Eingaben!$B$14="","",P10*12) -> 12896 | J10: =IF(Eingaben!$B$14="","",IF(O10=0,MAX(0,D10-P10*12),MAX(0,D10*(1+O10)^12-P10*((1+O10)^12-1)/O10))) -> 231110.6 | K10: =IF(Eingaben!$B$14="","",Eingaben!$M$14) -> 1200 | L10: =IF(Eingaben!$B$14="","",'Steuer & AfA'!L10) -> 1417.5188 | M10: =IF(Eingaben!$B$14="","",E10+L10-I10-K10) -> -2476.2447 | N10: =IF(Eingaben!$B$14="","",M10/12) -> -206.35372 | O10: =IF(Eingaben!$B$14="","",Eingaben!$AF$14) -> 0.0035 | P10: =IF(Eingaben!$B$14="","",Eingaben!$AE$14) -> 1074.6667
A11: 1 | B11: =IF(Eingaben!$B$14="","",Eingaben!$B$14) -> Musterwohnung Berlin | C11: 7 | D11: =IF(Eingaben!$B$14="","",J10) -> 231110.6 | E11: =IF(Eingaben!$B$14="","",Eingaben!$AC$14*12*(1+Eingaben!$K$14)^(7-1)) -> 10406.281 | F11: =IF(Eingaben!$B$14="","",E11/12) -> 867.19011 | G11: =IF(Eingaben!$B$14="","",I11-H11) -> 9644.5283 | H11: =IF(Eingaben!$B$14="","",D11-J11) -> 3251.4717 | I11: =IF(Eingaben!$B$14="","",P11*12) -> 12896 | J11: =IF(Eingaben!$B$14="","",IF(O11=0,MAX(0,D11-P11*12),MAX(0,D11*(1+O11)^12-P11*((1+O11)^12-1)/O11))) -> 227859.13 | K11: =IF(Eingaben!$B$14="","",Eingaben!$M$14) -> 1200 | L11: =IF(Eingaben!$B$14="","",'Steuer & AfA'!L11) -> 1282.4988 | M11: =IF(Eingaben!$B$14="","",E11+L11-I11-K11) -> -2407.2199 | N11: =IF(Eingaben!$B$14="","",M11/12) -> -200.60166 | O11: =IF(Eingaben!$B$14="","",Eingaben!$AF$14) -> 0.0035 | P11: =IF(Eingaben!$B$14="","",Eingaben!$AE$14) -> 1074.6667
A12: 1 | B12: =IF(Eingaben!$B$14="","",Eingaben!$B$14) -> Musterwohnung Berlin | C12: 8 | D12: =IF(Eingaben!$B$14="","",J11) -> 227859.13 | E12: =IF(Eingaben!$B$14="","",Eingaben!$AC$14*12*(1+Eingaben!$K$14)^(8-1)) -> 10614.407 | F12: =IF(Eingaben!$B$14="","",E12/12) -> 884.53391 | G12: =IF(Eingaben!$B$14="","",I12-H12) -> 9505.3068 | H12: =IF(Eingaben!$B$14="","",D12-J12) -> 3390.6932 | I12: =IF(Eingaben!$B$14="","",P12*12) -> 12896 | J12: =IF(Eingaben!$B$14="","",IF(O12=0,MAX(0,D12-P12*12),MAX(0,D12*(1+O12)^12-P12*((1+O12)^12-1)/O12))) -> 224468.44 | K12: =IF(Eingaben!$B$14="","",Eingaben!$M$14) -> 1200 | L12: =IF(Eingaben!$B$14="","",'Steuer & AfA'!L12) -> 1143.5599 | M12: =IF(Eingaben!$B$14="","",E12+L12-I12-K12) -> -2338.0331 | N12: =IF(Eingaben!$B$14="","",M12/12) -> -194.83609 | O12: =IF(Eingaben!$B$14="","",Eingaben!$AF$14) -> 0.0035 | P12: =IF(Eingaben!$B$14="","",Eingaben!$AE$14) -> 1074.6667
A13: 1 | B13: =IF(Eingaben!$B$14="","",Eingaben!$B$14) -> Musterwohnung Berlin | C13: 9 | D13: =IF(Eingaben!$B$14="","",J12) -> 224468.44 | E13: =IF(Eingaben!$B$14="","",Eingaben!$AC$14*12*(1+Eingaben!$K$14)^(9-1)) -> 10826.695 | F13: =IF(Eingaben!$B$14="","",E13/12) -> 902.22459 | G13: =IF(Eingaben!$B$14="","",I13-H13) -> 9360.1241 | H13: =IF(Eingaben!$B$14="","",D13-J13) -> 3535.8759 | I13: =IF(Eingaben!$B$14="","",P13*12) -> 12896 | J13: =IF(Eingaben!$B$14="","",IF(O13=0,MAX(0,D13-P13*12),MAX(0,D13*(1+O13)^12-P13*((1+O13)^12-1)/O13))) -> 220932.56 | K13: =IF(Eingaben!$B$14="","",Eingaben!$M$14) -> 1200 | L13: =IF(Eingaben!$B$14="","",'Steuer & AfA'!L13) -> 1000.5716 | M13: =IF(Eingaben!$B$14="","",E13+L13-I13-K13) -> -2268.7333 | N13: =IF(Eingaben!$B$14="","",M13/12) -> -189.06111 | O13: =IF(Eingaben!$B$14="","",Eingaben!$AF$14) -> 0.0035 | P13: =IF(Eingaben!$B$14="","",Eingaben!$AE$14) -> 1074.6667
A14: 1 | B14: =IF(Eingaben!$B$14="","",Eingaben!$B$14) -> Musterwohnung Berlin | C14: 10 | D14: =IF(Eingaben!$B$14="","",J13) -> 220932.56 | E14: =IF(Eingaben!$B$14="","",Eingaben!$AC$14*12*(1+Eingaben!$K$14)^(10-1)) -> 11043.229 | F14: =IF(Eingaben!$B$14="","",E14/12) -> 920.26908 | G14: =IF(Eingaben!$B$14="","",I14-H14) -> 9208.7249 | H14: =IF(Eingaben!$B$14="","",D14-J14) -> 3687.2751 | I14: =IF(Eingaben!$B$14="","",P14*12) -> 12896 | J14: =IF(Eingaben!$B$14="","",IF(O14=0,MAX(0,D14-P14*12),MAX(0,D14*(1+O14)^12-P14*((1+O14)^12-1)/O14))) -> 217245.29 | K14: =IF(Eingaben!$B$14="","",Eingaben!$M$14) -> 1200 | L14: =IF(Eingaben!$B$14="","",'Steuer & AfA'!L14) -> 853.39838 | M14: =IF(Eingaben!$B$14="","",E14+L14-I14-K14) -> -2199.3726 | N14: =IF(Eingaben!$B$14="","",M14/12) -> -183.28105 | O14: =IF(Eingaben!$B$14="","",Eingaben!$AF$14) -> 0.0035 | P14: =IF(Eingaben!$B$14="","",Eingaben!$AE$14) -> 1074.6667
A15: 2 | B15: =IF(Eingaben!$B$15="","",Eingaben!$B$15) | C15: 1 | D15: =IF(Eingaben!$B$15="","",Eingaben!$AB$15) | E15: =IF(Eingaben!$B$15="","",Eingaben!$AC$15*12*(1+Eingaben!$K$15)^(1-1)) | F15: =IF(Eingaben!$B$15="","",E15/12) | G15: =IF(Eingaben!$B$15="","",I15-H15) | H15: =IF(Eingaben!$B$15="","",D15-J15) | I15: =IF(Eingaben!$B$15="","",P15*12) | J15: =IF(Eingaben!$B$15="","",IF(O15=0,MAX(0,D15-P15*12),MAX(0,D15*(1+O15)^12-P15*((1+O15)^12-1)/O15))) | K15: =IF(Eingaben!$B$15="","",Eingaben!$M$15) | L15: =IF(Eingaben!$B$15="","",'Steuer & AfA'!L15) | M15: =IF(Eingaben!$B$15="","",E15+L15-I15-K15) | N15: =IF(Eingaben!$B$15="","",M15/12) | O15: =IF(Eingaben!$B$15="","",Eingaben!$AF$15) | P15: =IF(Eingaben!$B$15="","",Eingaben!$AE$15)
A16: 2 | B16: =IF(Eingaben!$B$15="","",Eingaben!$B$15) | C16: 2 | D16: =IF(Eingaben!$B$15="","",J15) | E16: =IF(Eingaben!$B$15="","",Eingaben!$AC$15*12*(1+Eingaben!$K$15)^(2-1)) | F16: =IF(Eingaben!$B$15="","",E16/12) | G16: =IF(Eingaben!$B$15="","",I16-H16) | H16: =IF(Eingaben!$B$15="","",D16-J16) | I16: =IF(Eingaben!$B$15="","",P16*12) | J16: =IF(Eingaben!$B$15="","",IF(O16=0,MAX(0,D16-P16*12),MAX(0,D16*(1+O16)^12-P16*((1+O16)^12-1)/O16))) | K16: =IF(Eingaben!$B$15="","",Eingaben!$M$15) | L16: =IF(Eingaben!$B$15="","",'Steuer & AfA'!L16) | M16: =IF(Eingaben!$B$15="","",E16+L16-I16-K16) | N16: =IF(Eingaben!$B$15="","",M16/12) | O16: =IF(Eingaben!$B$15="","",Eingaben!$AF$15) | P16: =IF(Eingaben!$B$15="","",Eingaben!$AE$15)
A17: 2 | B17: =IF(Eingaben!$B$15="","",Eingaben!$B$15) | C17: 3 | D17: =IF(Eingaben!$B$15="","",J16) | E17: =IF(Eingaben!$B$15="","",Eingaben!$AC$15*12*(1+Eingaben!$K$15)^(3-1)) | F17: =IF(Eingaben!$B$15="","",E17/12) | G17: =IF(Eingaben!$B$15="","",I17-H17) | H17: =IF(Eingaben!$B$15="","",D17-J17) | I17: =IF(Eingaben!$B$15="","",P17*12) | J17: =IF(Eingaben!$B$15="","",IF(O17=0,MAX(0,D17-P17*12),MAX(0,D17*(1+O17)^12-P17*((1+O17)^12-1)/O17))) | K17: =IF(Eingaben!$B$15="","",Eingaben!$M$15) | L17: =IF(Eingaben!$B$15="","",'Steuer & AfA'!L17) | M17: =IF(Eingaben!$B$15="","",E17+L17-I17-K17) | N17: =IF(Eingaben!$B$15="","",M17/12) | O17: =IF(Eingaben!$B$15="","",Eingaben!$AF$15) | P17: =IF(Eingaben!$B$15="","",Eingaben!$AE$15)
A18: 2 | B18: =IF(Eingaben!$B$15="","",Eingaben!$B$15) | C18: 4 | D18: =IF(Eingaben!$B$15="","",J17) | E18: =IF(Eingaben!$B$15="","",Eingaben!$AC$15*12*(1+Eingaben!$K$15)^(4-1)) | F18: =IF(Eingaben!$B$15="","",E18/12) | G18: =IF(Eingaben!$B$15="","",I18-H18) | H18: =IF(Eingaben!$B$15="","",D18-J18) | I18: =IF(Eingaben!$B$15="","",P18*12) | J18: =IF(Eingaben!$B$15="","",IF(O18=0,MAX(0,D18-P18*12),MAX(0,D18*(1+O18)^12-P18*((1+O18)^12-1)/O18))) | K18: =IF(Eingaben!$B$15="","",Eingaben!$M$15) | L18: =IF(Eingaben!$B$15="","",'Steuer & AfA'!L18) | M18: =IF(Eingaben!$B$15="","",E18+L18-I18-K18) | N18: =IF(Eingaben!$B$15="","",M18/12) | O18: =IF(Eingaben!$B$15="","",Eingaben!$AF$15) | P18: =IF(Eingaben!$B$15="","",Eingaben!$AE$15)
A19: 2 | B19: =IF(Eingaben!$B$15="","",Eingaben!$B$15) | C19: 5 | D19: =IF(Eingaben!$B$15="","",J18) | E19: =IF(Eingaben!$B$15="","",Eingaben!$AC$15*12*(1+Eingaben!$K$15)^(5-1)) | F19: =IF(Eingaben!$B$15="","",E19/12) | G19: =IF(Eingaben!$B$15="","",I19-H19) | H19: =IF(Eingaben!$B$15="","",D19-J19) | I19: =IF(Eingaben!$B$15="","",P19*12) | J19: =IF(Eingaben!$B$15="","",IF(O19=0,MAX(0,D19-P19*12),MAX(0,D19*(1+O19)^12-P19*((1+O19)^12-1)/O19))) | K19: =IF(Eingaben!$B$15="","",Eingaben!$M$15) | L19: =IF(Eingaben!$B$15="","",'Steuer & AfA'!L19) | M19: =IF(Eingaben!$B$15="","",E19+L19-I19-K19) | N19: =IF(Eingaben!$B$15="","",M19/12) | O19: =IF(Eingaben!$B$15="","",Eingaben!$AF$15) | P19: =IF(Eingaben!$B$15="","",Eingaben!$AE$15)
A20: 2 | B20: =IF(Eingaben!$B$15="","",Eingaben!$B$15) | C20: 6 | D20: =IF(Eingaben!$B$15="","",J19) | E20: =IF(Eingaben!$B$15="","",Eingaben!$AC$15*12*(1+Eingaben!$K$15)^(6-1)) | F20: =IF(Eingaben!$B$15="","",E20/12) | G20: =IF(Eingaben!$B$15="","",I20-H20) | H20: =IF(Eingaben!$B$15="","",D20-J20) | I20: =IF(Eingaben!$B$15="","",P20*12) | J20: =IF(Eingaben!$B$15="","",IF(O20=0,MAX(0,D20-P20*12),MAX(0,D20*(1+O20)^12-P20*((1+O20)^12-1)/O20))) | K20: =IF(Eingaben!$B$15="","",Eingaben!$M$15) | L20: =IF(Eingaben!$B$15="","",'Steuer & AfA'!L20) | M20: =IF(Eingaben!$B$15="","",E20+L20-I20-K20) | N20: =IF(Eingaben!$B$15="","",M20/12) | O20: =IF(Eingaben!$B$15="","",Eingaben!$AF$15) | P20: =IF(Eingaben!$B$15="","",Eingaben!$AE$15)
A21: 2 | B21: =IF(Eingaben!$B$15="","",Eingaben!$B$15) | C21: 7 | D21: =IF(Eingaben!$B$15="","",J20) | E21: =IF(Eingaben!$B$15="","",Eingaben!$AC$15*12*(1+Eingaben!$K$15)^(7-1)) | F21: =IF(Eingaben!$B$15="","",E21/12) | G21: =IF(Eingaben!$B$15="","",I21-H21) | H21: =IF(Eingaben!$B$15="","",D21-J21) | I21: =IF(Eingaben!$B$15="","",P21*12) | J21: =IF(Eingaben!$B$15="","",IF(O21=0,MAX(0,D21-P21*12),MAX(0,D21*(1+O21)^12-P21*((1+O21)^12-1)/O21))) | K21: =IF(Eingaben!$B$15="","",Eingaben!$M$15) | L21: =IF(Eingaben!$B$15="","",'Steuer & AfA'!L21) | M21: =IF(Eingaben!$B$15="","",E21+L21-I21-K21) | N21: =IF(Eingaben!$B$15="","",M21/12) | O21: =IF(Eingaben!$B$15="","",Eingaben!$AF$15) | P21: =IF(Eingaben!$B$15="","",Eingaben!$AE$15)
A22: 2 | B22: =IF(Eingaben!$B$15="","",Eingaben!$B$15) | C22: 8 | D22: =IF(Eingaben!$B$15="","",J21) | E22: =IF(Eingaben!$B$15="","",Eingaben!$AC$15*12*(1+Eingaben!$K$15)^(8-1)) | F22: =IF(Eingaben!$B$15="","",E22/12) | G22: =IF(Eingaben!$B$15="","",I22-H22) | H22: =IF(Eingaben!$B$15="","",D22-J22) | I22: =IF(Eingaben!$B$15="","",P22*12) | J22: =IF(Eingaben!$B$15="","",IF(O22=0,MAX(0,D22-P22*12),MAX(0,D22*(1+O22)^12-P22*((1+O22)^12-1)/O22))) | K22: =IF(Eingaben!$B$15="","",Eingaben!$M$15) | L22: =IF(Eingaben!$B$15="","",'Steuer & AfA'!L22) | M22: =IF(Eingaben!$B$15="","",E22+L22-I22-K22) | N22: =IF(Eingaben!$B$15="","",M22/12) | O22: =IF(Eingaben!$B$15="","",Eingaben!$AF$15) | P22: =IF(Eingaben!$B$15="","",Eingaben!$AE$15)
A23: 2 | B23: =IF(Eingaben!$B$15="","",Eingaben!$B$15) | C23: 9 | D23: =IF(Eingaben!$B$15="","",J22) | E23: =IF(Eingaben!$B$15="","",Eingaben!$AC$15*12*(1+Eingaben!$K$15)^(9-1)) | F23: =IF(Eingaben!$B$15="","",E23/12) | G23: =IF(Eingaben!$B$15="","",I23-H23) | H23: =IF(Eingaben!$B$15="","",D23-J23) | I23: =IF(Eingaben!$B$15="","",P23*12) | J23: =IF(Eingaben!$B$15="","",IF(O23=0,MAX(0,D23-P23*12),MAX(0,D23*(1+O23)^12-P23*((1+O23)^12-1)/O23))) | K23: =IF(Eingaben!$B$15="","",Eingaben!$M$15) | L23: =IF(Eingaben!$B$15="","",'Steuer & AfA'!L23) | M23: =IF(Eingaben!$B$15="","",E23+L23-I23-K23) | N23: =IF(Eingaben!$B$15="","",M23/12) | O23: =IF(Eingaben!$B$15="","",Eingaben!$AF$15) | P23: =IF(Eingaben!$B$15="","",Eingaben!$AE$15)
A24: 2 | B24: =IF(Eingaben!$B$15="","",Eingaben!$B$15) | C24: 10 | D24: =IF(Eingaben!$B$15="","",J23) | E24: =IF(Eingaben!$B$15="","",Eingaben!$AC$15*12*(1+Eingaben!$K$15)^(10-1)) | F24: =IF(Eingaben!$B$15="","",E24/12) | G24: =IF(Eingaben!$B$15="","",I24-H24) | H24: =IF(Eingaben!$B$15="","",D24-J24) | I24: =IF(Eingaben!$B$15="","",P24*12) | J24: =IF(Eingaben!$B$15="","",IF(O24=0,MAX(0,D24-P24*12),MAX(0,D24*(1+O24)^12-P24*((1+O24)^12-1)/O24))) | K24: =IF(Eingaben!$B$15="","",Eingaben!$M$15) | L24: =IF(Eingaben!$B$15="","",'Steuer & AfA'!L24) | M24: =IF(Eingaben!$B$15="","",E24+L24-I24-K24) | N24: =IF(Eingaben!$B$15="","",M24/12) | O24: =IF(Eingaben!$B$15="","",Eingaben!$AF$15) | P24: =IF(Eingaben!$B$15="","",Eingaben!$AE$15)
A25: 3 | B25: =IF(Eingaben!$B$16="","",Eingaben!$B$16) | C25: 1 | D25: =IF(Eingaben!$B$16="","",Eingaben!$AB$16) | E25: =IF(Eingaben!$B$16="","",Eingaben!$AC$16*12*(1+Eingaben!$K$16)^(1-1)) | F25: =IF(Eingaben!$B$16="","",E25/12) | G25: =IF(Eingaben!$B$16="","",I25-H25) | H25: =IF(Eingaben!$B$16="","",D25-J25) | I25: =IF(Eingaben!$B$16="","",P25*12) | J25: =IF(Eingaben!$B$16="","",IF(O25=0,MAX(0,D25-P25*12),MAX(0,D25*(1+O25)^12-P25*((1+O25)^12-1)/O25))) | K25: =IF(Eingaben!$B$16="","",Eingaben!$M$16) | L25: =IF(Eingaben!$B$16="","",'Steuer & AfA'!L25) | M25: =IF(Eingaben!$B$16="","",E25+L25-I25-K25) | N25: =IF(Eingaben!$B$16="","",M25/12) | O25: =IF(Eingaben!$B$16="","",Eingaben!$AF$16) | P25: =IF(Eingaben!$B$16="","",Eingaben!$AE$16)
A26: 3 | B26: =IF(Eingaben!$B$16="","",Eingaben!$B$16) | C26: 2 | D26: =IF(Eingaben!$B$16="","",J25) | E26: =IF(Eingaben!$B$16="","",Eingaben!$AC$16*12*(1+Eingaben!$K$16)^(2-1)) | F26: =IF(Eingaben!$B$16="","",E26/12) | G26: =IF(Eingaben!$B$16="","",I26-H26) | H26: =IF(Eingaben!$B$16="","",D26-J26) | I26: =IF(Eingaben!$B$16="","",P26*12) | J26: =IF(Eingaben!$B$16="","",IF(O26=0,MAX(0,D26-P26*12),MAX(0,D26*(1+O26)^12-P26*((1+O26)^12-1)/O26))) | K26: =IF(Eingaben!$B$16="","",Eingaben!$M$16) | L26: =IF(Eingaben!$B$16="","",'Steuer & AfA'!L26) | M26: =IF(Eingaben!$B$16="","",E26+L26-I26-K26) | N26: =IF(Eingaben!$B$16="","",M26/12) | O26: =IF(Eingaben!$B$16="","",Eingaben!$AF$16) | P26: =IF(Eingaben!$B$16="","",Eingaben!$AE$16)
A27: 3 | B27: =IF(Eingaben!$B$16="","",Eingaben!$B$16) | C27: 3 | D27: =IF(Eingaben!$B$16="","",J26) | E27: =IF(Eingaben!$B$16="","",Eingaben!$AC$16*12*(1+Eingaben!$K$16)^(3-1)) | F27: =IF(Eingaben!$B$16="","",E27/12) | G27: =IF(Eingaben!$B$16="","",I27-H27) | H27: =IF(Eingaben!$B$16="","",D27-J27) | I27: =IF(Eingaben!$B$16="","",P27*12) | J27: =IF(Eingaben!$B$16="","",IF(O27=0,MAX(0,D27-P27*12),MAX(0,D27*(1+O27)^12-P27*((1+O27)^12-1)/O27))) | K27: =IF(Eingaben!$B$16="","",Eingaben!$M$16) | L27: =IF(Eingaben!$B$16="","",'Steuer & AfA'!L27) | M27: =IF(Eingaben!$B$16="","",E27+L27-I27-K27) | N27: =IF(Eingaben!$B$16="","",M27/12) | O27: =IF(Eingaben!$B$16="","",Eingaben!$AF$16) | P27: =IF(Eingaben!$B$16="","",Eingaben!$AE$16)
A28: 3 | B28: =IF(Eingaben!$B$16="","",Eingaben!$B$16) | C28: 4 | D28: =IF(Eingaben!$B$16="","",J27) | E28: =IF(Eingaben!$B$16="","",Eingaben!$AC$16*12*(1+Eingaben!$K$16)^(4-1)) | F28: =IF(Eingaben!$B$16="","",E28/12) | G28: =IF(Eingaben!$B$16="","",I28-H28) | H28: =IF(Eingaben!$B$16="","",D28-J28) | I28: =IF(Eingaben!$B$16="","",P28*12) | J28: =IF(Eingaben!$B$16="","",IF(O28=0,MAX(0,D28-P28*12),MAX(0,D28*(1+O28)^12-P28*((1+O28)^12-1)/O28))) | K28: =IF(Eingaben!$B$16="","",Eingaben!$M$16) | L28: =IF(Eingaben!$B$16="","",'Steuer & AfA'!L28) | M28: =IF(Eingaben!$B$16="","",E28+L28-I28-K28) | N28: =IF(Eingaben!$B$16="","",M28/12) | O28: =IF(Eingaben!$B$16="","",Eingaben!$AF$16) | P28: =IF(Eingaben!$B$16="","",Eingaben!$AE$16)
A29: 3 | B29: =IF(Eingaben!$B$16="","",Eingaben!$B$16) | C29: 5 | D29: =IF(Eingaben!$B$16="","",J28) | E29: =IF(Eingaben!$B$16="","",Eingaben!$AC$16*12*(1+Eingaben!$K$16)^(5-1)) | F29: =IF(Eingaben!$B$16="","",E29/12) | G29: =IF(Eingaben!$B$16="","",I29-H29) | H29: =IF(Eingaben!$B$16="","",D29-J29) | I29: =IF(Eingaben!$B$16="","",P29*12) | J29: =IF(Eingaben!$B$16="","",IF(O29=0,MAX(0,D29-P29*12),MAX(0,D29*(1+O29)^12-P29*((1+O29)^12-1)/O29))) | K29: =IF(Eingaben!$B$16="","",Eingaben!$M$16) | L29: =IF(Eingaben!$B$16="","",'Steuer & AfA'!L29) | M29: =IF(Eingaben!$B$16="","",E29+L29-I29-K29) | N29: =IF(Eingaben!$B$16="","",M29/12) | O29: =IF(Eingaben!$B$16="","",Eingaben!$AF$16) | P29: =IF(Eingaben!$B$16="","",Eingaben!$AE$16)
A30: 3 | B30: =IF(Eingaben!$B$16="","",Eingaben!$B$16) | C30: 6 | D30: =IF(Eingaben!$B$16="","",J29) | E30: =IF(Eingaben!$B$16="","",Eingaben!$AC$16*12*(1+Eingaben!$K$16)^(6-1)) | F30: =IF(Eingaben!$B$16="","",E30/12) | G30: =IF(Eingaben!$B$16="","",I30-H30) | H30: =IF(Eingaben!$B$16="","",D30-J30) | I30: =IF(Eingaben!$B$16="","",P30*12) | J30: =IF(Eingaben!$B$16="","",IF(O30=0,MAX(0,D30-P30*12),MAX(0,D30*(1+O30)^12-P30*((1+O30)^12-1)/O30))) | K30: =IF(Eingaben!$B$16="","",Eingaben!$M$16) | L30: =IF(Eingaben!$B$16="","",'Steuer & AfA'!L30) | M30: =IF(Eingaben!$B$16="","",E30+L30-I30-K30) | N30: =IF(Eingaben!$B$16="","",M30/12) | O30: =IF(Eingaben!$B$16="","",Eingaben!$AF$16) | P30: =IF(Eingaben!$B$16="","",Eingaben!$AE$16)
A31: 3 | B31: =IF(Eingaben!$B$16="","",Eingaben!$B$16) | C31: 7 | D31: =IF(Eingaben!$B$16="","",J30) | E31: =IF(Eingaben!$B$16="","",Eingaben!$AC$16*12*(1+Eingaben!$K$16)^(7-1)) | F31: =IF(Eingaben!$B$16="","",E31/12) | G31: =IF(Eingaben!$B$16="","",I31-H31) | H31: =IF(Eingaben!$B$16="","",D31-J31) | I31: =IF(Eingaben!$B$16="","",P31*12) | J31: =IF(Eingaben!$B$16="","",IF(O31=0,MAX(0,D31-P31*12),MAX(0,D31*(1+O31)^12-P31*((1+O31)^12-1)/O31))) | K31: =IF(Eingaben!$B$16="","",Eingaben!$M$16) | L31: =IF(Eingaben!$B$16="","",'Steuer & AfA'!L31) | M31: =IF(Eingaben!$B$16="","",E31+L31-I31-K31) | N31: =IF(Eingaben!$B$16="","",M31/12) | O31: =IF(Eingaben!$B$16="","",Eingaben!$AF$16) | P31: =IF(Eingaben!$B$16="","",Eingaben!$AE$16)
A32: 3 | B32: =IF(Eingaben!$B$16="","",Eingaben!$B$16) | C32: 8 | D32: =IF(Eingaben!$B$16="","",J31) | E32: =IF(Eingaben!$B$16="","",Eingaben!$AC$16*12*(1+Eingaben!$K$16)^(8-1)) | F32: =IF(Eingaben!$B$16="","",E32/12) | G32: =IF(Eingaben!$B$16="","",I32-H32) | H32: =IF(Eingaben!$B$16="","",D32-J32) | I32: =IF(Eingaben!$B$16="","",P32*12) | J32: =IF(Eingaben!$B$16="","",IF(O32=0,MAX(0,D32-P32*12),MAX(0,D32*(1+O32)^12-P32*((1+O32)^12-1)/O32))) | K32: =IF(Eingaben!$B$16="","",Eingaben!$M$16) | L32: =IF(Eingaben!$B$16="","",'Steuer & AfA'!L32) | M32: =IF(Eingaben!$B$16="","",E32+L32-I32-K32) | N32: =IF(Eingaben!$B$16="","",M32/12) | O32: =IF(Eingaben!$B$16="","",Eingaben!$AF$16) | P32: =IF(Eingaben!$B$16="","",Eingaben!$AE$16)
A33: 3 | B33: =IF(Eingaben!$B$16="","",Eingaben!$B$16) | C33: 9 | D33: =IF(Eingaben!$B$16="","",J32) | E33: =IF(Eingaben!$B$16="","",Eingaben!$AC$16*12*(1+Eingaben!$K$16)^(9-1)) | F33: =IF(Eingaben!$B$16="","",E33/12) | G33: =IF(Eingaben!$B$16="","",I33-H33) | H33: =IF(Eingaben!$B$16="","",D33-J33) | I33: =IF(Eingaben!$B$16="","",P33*12) | J33: =IF(Eingaben!$B$16="","",IF(O33=0,MAX(0,D33-P33*12),MAX(0,D33*(1+O33)^12-P33*((1+O33)^12-1)/O33))) | K33: =IF(Eingaben!$B$16="","",Eingaben!$M$16) | L33: =IF(Eingaben!$B$16="","",'Steuer & AfA'!L33) | M33: =IF(Eingaben!$B$16="","",E33+L33-I33-K33) | N33: =IF(Eingaben!$B$16="","",M33/12) | O33: =IF(Eingaben!$B$16="","",Eingaben!$AF$16) | P33: =IF(Eingaben!$B$16="","",Eingaben!$AE$16)
A34: 3 | B34: =IF(Eingaben!$B$16="","",Eingaben!$B$16) | C34: 10 | D34: =IF(Eingaben!$B$16="","",J33) | E34: =IF(Eingaben!$B$16="","",Eingaben!$AC$16*12*(1+Eingaben!$K$16)^(10-1)) | F34: =IF(Eingaben!$B$16="","",E34/12) | G34: =IF(Eingaben!$B$16="","",I34-H34) | H34: =IF(Eingaben!$B$16="","",D34-J34) | I34: =IF(Eingaben!$B$16="","",P34*12) | J34: =IF(Eingaben!$B$16="","",IF(O34=0,MAX(0,D34-P34*12),MAX(0,D34*(1+O34)^12-P34*((1+O34)^12-1)/O34))) | K34: =IF(Eingaben!$B$16="","",Eingaben!$M$16) | L34: =IF(Eingaben!$B$16="","",'Steuer & AfA'!L34) | M34: =IF(Eingaben!$B$16="","",E34+L34-I34-K34) | N34: =IF(Eingaben!$B$16="","",M34/12) | O34: =IF(Eingaben!$B$16="","",Eingaben!$AF$16) | P34: =IF(Eingaben!$B$16="","",Eingaben!$AE$16)
A35: 4 | B35: =IF(Eingaben!$B$17="","",Eingaben!$B$17) | C35: 1 | D35: =IF(Eingaben!$B$17="","",Eingaben!$AB$17) | E35: =IF(Eingaben!$B$17="","",Eingaben!$AC$17*12*(1+Eingaben!$K$17)^(1-1)) | F35: =IF(Eingaben!$B$17="","",E35/12) | G35: =IF(Eingaben!$B$17="","",I35-H35) | H35: =IF(Eingaben!$B$17="","",D35-J35) | I35: =IF(Eingaben!$B$17="","",P35*12) | J35: =IF(Eingaben!$B$17="","",IF(O35=0,MAX(0,D35-P35*12),MAX(0,D35*(1+O35)^12-P35*((1+O35)^12-1)/O35))) | K35: =IF(Eingaben!$B$17="","",Eingaben!$M$17) | L35: =IF(Eingaben!$B$17="","",'Steuer & AfA'!L35) | M35: =IF(Eingaben!$B$17="","",E35+L35-I35-K35) | N35: =IF(Eingaben!$B$17="","",M35/12) | O35: =IF(Eingaben!$B$17="","",Eingaben!$AF$17) | P35: =IF(Eingaben!$B$17="","",Eingaben!$AE$17)
A36: 4 | B36: =IF(Eingaben!$B$17="","",Eingaben!$B$17) | C36: 2 | D36: =IF(Eingaben!$B$17="","",J35) | E36: =IF(Eingaben!$B$17="","",Eingaben!$AC$17*12*(1+Eingaben!$K$17)^(2-1)) | F36: =IF(Eingaben!$B$17="","",E36/12) | G36: =IF(Eingaben!$B$17="","",I36-H36) | H36: =IF(Eingaben!$B$17="","",D36-J36) | I36: =IF(Eingaben!$B$17="","",P36*12) | J36: =IF(Eingaben!$B$17="","",IF(O36=0,MAX(0,D36-P36*12),MAX(0,D36*(1+O36)^12-P36*((1+O36)^12-1)/O36))) | K36: =IF(Eingaben!$B$17="","",Eingaben!$M$17) | L36: =IF(Eingaben!$B$17="","",'Steuer & AfA'!L36) | M36: =IF(Eingaben!$B$17="","",E36+L36-I36-K36) | N36: =IF(Eingaben!$B$17="","",M36/12) | O36: =IF(Eingaben!$B$17="","",Eingaben!$AF$17) | P36: =IF(Eingaben!$B$17="","",Eingaben!$AE$17)
A37: 4 | B37: =IF(Eingaben!$B$17="","",Eingaben!$B$17) | C37: 3 | D37: =IF(Eingaben!$B$17="","",J36) | E37: =IF(Eingaben!$B$17="","",Eingaben!$AC$17*12*(1+Eingaben!$K$17)^(3-1)) | F37: =IF(Eingaben!$B$17="","",E37/12) | G37: =IF(Eingaben!$B$17="","",I37-H37) | H37: =IF(Eingaben!$B$17="","",D37-J37) | I37: =IF(Eingaben!$B$17="","",P37*12) | J37: =IF(Eingaben!$B$17="","",IF(O37=0,MAX(0,D37-P37*12),MAX(0,D37*(1+O37)^12-P37*((1+O37)^12-1)/O37))) | K37: =IF(Eingaben!$B$17="","",Eingaben!$M$17) | L37: =IF(Eingaben!$B$17="","",'Steuer & AfA'!L37) | M37: =IF(Eingaben!$B$17="","",E37+L37-I37-K37) | N37: =IF(Eingaben!$B$17="","",M37/12) | O37: =IF(Eingaben!$B$17="","",Eingaben!$AF$17) | P37: =IF(Eingaben!$B$17="","",Eingaben!$AE$17)
A38: 4 | B38: =IF(Eingaben!$B$17="","",Eingaben!$B$17) | C38: 4 | D38: =IF(Eingaben!$B$17="","",J37) | E38: =IF(Eingaben!$B$17="","",Eingaben!$AC$17*12*(1+Eingaben!$K$17)^(4-1)) | F38: =IF(Eingaben!$B$17="","",E38/12) | G38: =IF(Eingaben!$B$17="","",I38-H38) | H38: =IF(Eingaben!$B$17="","",D38-J38) | I38: =IF(Eingaben!$B$17="","",P38*12) | J38: =IF(Eingaben!$B$17="","",IF(O38=0,MAX(0,D38-P38*12),MAX(0,D38*(1+O38)^12-P38*((1+O38)^12-1)/O38))) | K38: =IF(Eingaben!$B$17="","",Eingaben!$M$17) | L38: =IF(Eingaben!$B$17="","",'Steuer & AfA'!L38) | M38: =IF(Eingaben!$B$17="","",E38+L38-I38-K38) | N38: =IF(Eingaben!$B$17="","",M38/12) | O38: =IF(Eingaben!$B$17="","",Eingaben!$AF$17) | P38: =IF(Eingaben!$B$17="","",Eingaben!$AE$17)
A39: 4 | B39: =IF(Eingaben!$B$17="","",Eingaben!$B$17) | C39: 5 | D39: =IF(Eingaben!$B$17="","",J38) | E39: =IF(Eingaben!$B$17="","",Eingaben!$AC$17*12*(1+Eingaben!$K$17)^(5-1)) | F39: =IF(Eingaben!$B$17="","",E39/12) | G39: =IF(Eingaben!$B$17="","",I39-H39) | H39: =IF(Eingaben!$B$17="","",D39-J39) | I39: =IF(Eingaben!$B$17="","",P39*12) | J39: =IF(Eingaben!$B$17="","",IF(O39=0,MAX(0,D39-P39*12),MAX(0,D39*(1+O39)^12-P39*((1+O39)^12-1)/O39))) | K39: =IF(Eingaben!$B$17="","",Eingaben!$M$17) | L39: =IF(Eingaben!$B$17="","",'Steuer & AfA'!L39) | M39: =IF(Eingaben!$B$17="","",E39+L39-I39-K39) | N39: =IF(Eingaben!$B$17="","",M39/12) | O39: =IF(Eingaben!$B$17="","",Eingaben!$AF$17) | P39: =IF(Eingaben!$B$17="","",Eingaben!$AE$17)
A40: 4 | B40: =IF(Eingaben!$B$17="","",Eingaben!$B$17) | C40: 6 | D40: =IF(Eingaben!$B$17="","",J39) | E40: =IF(Eingaben!$B$17="","",Eingaben!$AC$17*12*(1+Eingaben!$K$17)^(6-1)) | F40: =IF(Eingaben!$B$17="","",E40/12) | G40: =IF(Eingaben!$B$17="","",I40-H40) | H40: =IF(Eingaben!$B$17="","",D40-J40) | I40: =IF(Eingaben!$B$17="","",P40*12) | J40: =IF(Eingaben!$B$17="","",IF(O40=0,MAX(0,D40-P40*12),MAX(0,D40*(1+O40)^12-P40*((1+O40)^12-1)/O40))) | K40: =IF(Eingaben!$B$17="","",Eingaben!$M$17) | L40: =IF(Eingaben!$B$17="","",'Steuer & AfA'!L40) | M40: =IF(Eingaben!$B$17="","",E40+L40-I40-K40) | N40: =IF(Eingaben!$B$17="","",M40/12) | O40: =IF(Eingaben!$B$17="","",Eingaben!$AF$17) | P40: =IF(Eingaben!$B$17="","",Eingaben!$AE$17)
A41: 4 | B41: =IF(Eingaben!$B$17="","",Eingaben!$B$17) | C41: 7 | D41: =IF(Eingaben!$B$17="","",J40) | E41: =IF(Eingaben!$B$17="","",Eingaben!$AC$17*12*(1+Eingaben!$K$17)^(7-1)) | F41: =IF(Eingaben!$B$17="","",E41/12) | G41: =IF(Eingaben!$B$17="","",I41-H41) | H41: =IF(Eingaben!$B$17="","",D41-J41) | I41: =IF(Eingaben!$B$17="","",P41*12) | J41: =IF(Eingaben!$B$17="","",IF(O41=0,MAX(0,D41-P41*12),MAX(0,D41*(1+O41)^12-P41*((1+O41)^12-1)/O41))) | K41: =IF(Eingaben!$B$17="","",Eingaben!$M$17) | L41: =IF(Eingaben!$B$17="","",'Steuer & AfA'!L41) | M41: =IF(Eingaben!$B$17="","",E41+L41-I41-K41) | N41: =IF(Eingaben!$B$17="","",M41/12) | O41: =IF(Eingaben!$B$17="","",Eingaben!$AF$17) | P41: =IF(Eingaben!$B$17="","",Eingaben!$AE$17)
...

Sheet Steuer & AfA
A1: 🧾 Steuer & AfA – 10-Jahres-Verlauf je Immobilie
A2: AfA-Schedule und Steuervergleich (ohne/mit Immobilie) je Immobilie und Jahr. Isolierte Betrachtung je Objekt gegen das Haushaltseinkommen (vereinfachte Modellrechnung).
A4: Nr. | B4: Immobilie | C4: Jahr | D4: Restbuchwert Jahresanfang (€) | E4: Basis-AfA (€) | F4: Sonder-AfA (€) | G4: AfA gesamt (€) | H4: Restbuchwert Jahresende (€) | I4: Steuerliches Ergebnis (€) | J4: Steuer ohne Immobilie (€) | K4: Steuer mit Immobilie (€) | L4: Steuerwirkung (€) | N4: ZvE eff. ohne | O4: Basissteuer ohne | P4: ZvE eff. mit | Q4: Basissteuer mit
A5: 1 | B5: =IF(Eingaben!$B$14="","",Cashflow!B5) -> Musterwohnung Berlin | C5: 1 | D5: =IF(Eingaben!$B$14="","",Eingaben!$AD$14) -> 198400 | E5: =IF(Eingaben!$B$14="","",MIN(D5,MAX(0,IF(Eingaben!$S$14="Ja",D5*Eingaben!$T$14,Eingaben!$AD$14*Eingaben!$Q$14)))) -> 3968 | F5: =IF(Eingaben!$B$14="","",MIN(MAX(0,IF(AND(Eingaben!$U$14="Ja",1<=Eingaben!$W$14),Eingaben!$AD$14*Eingaben!$V$14,0)),MAX(0,D5-E5))) -> 0 | G5: =IF(Eingaben!$B$14="","",E5+F5) -> 3968 | H5: =IF(Eingaben!$B$14="","",D5-G5) -> 194432 | I5: =IF(Eingaben!$B$14="","",Cashflow!E5-Cashflow!G5-G5) -> -5095.2186 | J5: =IF(Eingaben!$B$14="","",IF(Eingaben!$D$6="Ja",2*MAX(0,O5),MAX(0,O5))) -> 0 | K5: =IF(Eingaben!$B$14="","",IF(Eingaben!$D$6="Ja",2*MAX(0,Q5),MAX(0,Q5))) -> 0 | L5: =IF(Eingaben!$B$14="","",IF(Eingaben!$D$5>0,J5-K5,-I5*Eingaben!$D$9)) -> 2038.0874 | N5: =IF(Eingaben!$B$14="","",IF(Eingaben!$D$6="Ja",Eingaben!$F$6/2,Eingaben!$F$6)) -> 0 | O5: =IF(Eingaben!$B$14="","",IF(N5<=12348,0,IF(N5<=17799,(914.51*((N5-12348)/10000)+1400)*((N5-12348)/10000),IF(N5<=69878,(181.19*((N5-17799)/10000)+2397)*((N5-17799)/10000)+1025.38,IF(N5<=277825,0.42*N5-10637.32,0.45*N5-18971.07))))) -> 0 | P5: =IF(Eingaben!$B$14="","",IF(Eingaben!$D$6="Ja",MAX(0,Eingaben!$F$6+I5)/2,MAX(0,Eingaben!$F$6+I5))) -> 0 | Q5: =IF(Eingaben!$B$14="","",IF(P5<=12348,0,IF(P5<=17799,(914.51*((P5-12348)/10000)+1400)*((P5-12348)/10000),IF(P5<=69878,(181.19*((P5-17799)/10000)+2397)*((P5-17799)/10000)+1025.38,IF(P5<=277825,0.42*P5-10637.32,0.45*P5-18971.07))))) -> 0
A6: 1 | B6: =IF(Eingaben!$B$14="","",Cashflow!B6) -> Musterwohnung Berlin | C6: 2 | D6: =IF(Eingaben!$B$14="","",H5) -> 194432 | E6: =IF(Eingaben!$B$14="","",MIN(D6,MAX(0,IF(Eingaben!$S$14="Ja",D6*Eingaben!$T$14,Eingaben!$AD$14*Eingaben!$Q$14)))) -> 3968 | F6: =IF(Eingaben!$B$14="","",MIN(MAX(0,IF(AND(Eingaben!$U$14="Ja",2<=Eingaben!$W$14),Eingaben!$AD$14*Eingaben!$V$14,0)),MAX(0,D6-E6))) -> 0 | G6: =IF(Eingaben!$B$14="","",E6+F6) -> 3968 | H6: =IF(Eingaben!$B$14="","",D6-G6) -> 190464 | I6: =IF(Eingaben!$B$14="","",Cashflow!E6-Cashflow!G6-G6) -> -4802.1522 | J6: =IF(Eingaben!$B$14="","",IF(Eingaben!$D$6="Ja",2*MAX(0,O6),MAX(0,O6))) -> 0 | K6: =IF(Eingaben!$B$14="","",IF(Eingaben!$D$6="Ja",2*MAX(0,Q6),MAX(0,Q6))) -> 0 | L6: =IF(Eingaben!$B$14="","",IF(Eingaben!$D$5>0,J6-K6,-I6*Eingaben!$D$9)) -> 1920.8609 | N6: =IF(Eingaben!$B$14="","",IF(Eingaben!$D$6="Ja",Eingaben!$F$6/2,Eingaben!$F$6)) -> 0 | O6: =IF(Eingaben!$B$14="","",IF(N6<=12348,0,IF(N6<=17799,(914.51*((N6-12348)/10000)+1400)*((N6-12348)/10000),IF(N6<=69878,(181.19*((N6-17799)/10000)+2397)*((N6-17799)/10000)+1025.38,IF(N6<=277825,0.42*N6-10637.32,0.45*N6-18971.07))))) -> 0 | P6: =IF(Eingaben!$B$14="","",IF(Eingaben!$D$6="Ja",MAX(0,Eingaben!$F$6+I6)/2,MAX(0,Eingaben!$F$6+I6))) -> 0 | Q6: =IF(Eingaben!$B$14="","",IF(P6<=12348,0,IF(P6<=17799,(914.51*((P6-12348)/10000)+1400)*((P6-12348)/10000),IF(P6<=69878,(181.19*((P6-17799)/10000)+2397)*((P6-17799)/10000)+1025.38,IF(P6<=277825,0.42*P6-10637.32,0.45*P6-18971.07))))) -> 0
A7: 1 | B7: =IF(Eingaben!$B$14="","",Cashflow!B7) -> Musterwohnung Berlin | C7: 3 | D7: =IF(Eingaben!$B$14="","",H6) -> 190464 | E7: =IF(Eingaben!$B$14="","",MIN(D7,MAX(0,IF(Eingaben!$S$14="Ja",D7*Eingaben!$T$14,Eingaben!$AD$14*Eingaben!$Q$14)))) -> 3968 | F7: =IF(Eingaben!$B$14="","",MIN(MAX(0,IF(AND(Eingaben!$U$14="Ja",3<=Eingaben!$W$14),Eingaben!$AD$14*Eingaben!$V$14,0)),MAX(0,D7-E7))) -> 0 | G7: =IF(Eingaben!$B$14="","",E7+F7) -> 3968 | H7: =IF(Eingaben!$B$14="","",D7-G7) -> 186496 | I7: =IF(Eingaben!$B$14="","",Cashflow!E7-Cashflow!G7-G7) -> -4500.7542 | J7: =IF(Eingaben!$B$14="","",IF(Eingaben!$D$6="Ja",2*MAX(0,O7),MAX(0,O7))) -> 0 | K7: =IF(Eingaben!$B$14="","",IF(Eingaben!$D$6="Ja",2*MAX(0,Q7),MAX(0,Q7))) -> 0 | L7: =IF(Eingaben!$B$14="","",IF(Eingaben!$D$5>0,J7-K7,-I7*Eingaben!$D$9)) -> 1800.3017 | N7: =IF(Eingaben!$B$14="","",IF(Eingaben!$D$6="Ja",Eingaben!$F$6/2,Eingaben!$F$6)) -> 0 | O7: =IF(Eingaben!$B$14="","",IF(N7<=12348,0,IF(N7<=17799,(914.51*((N7-12348)/10000)+1400)*((N7-12348)/10000),IF(N7<=69878,(181.19*((N7-17799)/10000)+2397)*((N7-17799)/10000)+1025.38,IF(N7<=277825,0.42*N7-10637.32,0.45*N7-18971.07))))) -> 0 | P7: =IF(Eingaben!$B$14="","",IF(Eingaben!$D$6="Ja",MAX(0,Eingaben!$F$6+I7)/2,MAX(0,Eingaben!$F$6+I7))) -> 0 | Q7: =IF(Eingaben!$B$14="","",IF(P7<=12348,0,IF(P7<=17799,(914.51*((P7-12348)/10000)+1400)*((P7-12348)/10000),IF(P7<=69878,(181.19*((P7-17799)/10000)+2397)*((P7-17799)/10000)+1025.38,IF(P7<=277825,0.42*P7-10637.32,0.45*P7-18971.07))))) -> 0
A8: 1 | B8: =IF(Eingaben!$B$14="","",Cashflow!B8) -> Musterwohnung Berlin | C8: 4 | D8: =IF(Eingaben!$B$14="","",H7) -> 186496 | E8: =IF(Eingaben!$B$14="","",MIN(D8,MAX(0,IF(Eingaben!$S$14="Ja",D8*Eingaben!$T$14,Eingaben!$AD$14*Eingaben!$Q$14)))) -> 3968 | F8: =IF(Eingaben!$B$14="","",MIN(MAX(0,IF(AND(Eingaben!$U$14="Ja",4<=Eingaben!$W$14),Eingaben!$AD$14*Eingaben!$V$14,0)),MAX(0,D8-E8))) -> 0 | G8: =IF(Eingaben!$B$14="","",E8+F8) -> 3968 | H8: =IF(Eingaben!$B$14="","",D8-G8) -> 182528 | I8: =IF(Eingaben!$B$14="","",Cashflow!E8-Cashflow!G8-G8) -> -4190.7523 | J8: =IF(Eingaben!$B$14="","",IF(Eingaben!$D$6="Ja",2*MAX(0,O8),MAX(0,O8))) -> 0 | K8: =IF(Eingaben!$B$14="","",IF(Eingaben!$D$6="Ja",2*MAX(0,Q8),MAX(0,Q8))) -> 0 | L8: =IF(Eingaben!$B$14="","",IF(Eingaben!$D$5>0,J8-K8,-I8*Eingaben!$D$9)) -> 1676.3009 | N8: =IF(Eingaben!$B$14="","",IF(Eingaben!$D$6="Ja",Eingaben!$F$6/2,Eingaben!$F$6)) -> 0 | O8: =IF(Eingaben!$B$14="","",IF(N8<=12348,0,IF(N8<=17799,(914.51*((N8-12348)/10000)+1400)*((N8-12348)/10000),IF(N8<=69878,(181.19*((N8-17799)/10000)+2397)*((N8-17799)/10000)+1025.38,IF(N8<=277825,0.42*N8-10637.32,0.45*N8-18971.07))))) -> 0 | P8: =IF(Eingaben!$B$14="","",IF(Eingaben!$D$6="Ja",MAX(0,Eingaben!$F$6+I8)/2,MAX(0,Eingaben!$F$6+I8))) -> 0 | Q8: =IF(Eingaben!$B$14="","",IF(P8<=12348,0,IF(P8<=17799,(914.51*((P8-12348)/10000)+1400)*((P8-12348)/10000),IF(P8<=69878,(181.19*((P8-17799)/10000)+2397)*((P8-17799)/10000)+1025.38,IF(P8<=277825,0.42*P8-10637.32,0.45*P8-18971.07))))) -> 0
A9: 1 | B9: =IF(Eingaben!$B$14="","",Cashflow!B9) -> Musterwohnung Berlin | C9: 5 | D9: =IF(Eingaben!$B$14="","",H8) -> 182528 | E9: =IF(Eingaben!$B$14="","",MIN(D9,MAX(0,IF(Eingaben!$S$14="Ja",D9*Eingaben!$T$14,Eingaben!$AD$14*Eingaben!$Q$14)))) -> 3968 | F9: =IF(Eingaben!$B$14="","",MIN(MAX(0,IF(AND(Eingaben!$U$14="Ja",5<=Eingaben!$W$14),Eingaben!$AD$14*Eingaben!$V$14,0)),MAX(0,D9-E9))) -> 0 | G9: =IF(Eingaben!$B$14="","",E9+F9) -> 3968 | H9: =IF(Eingaben!$B$14="","",D9-G9) -> 178560 | I9: =IF(Eingaben!$B$14="","",Cashflow!E9-Cashflow!G9-G9) -> -3871.8641 | J9: =IF(Eingaben!$B$14="","",IF(Eingaben!$D$6="Ja",2*MAX(0,O9),MAX(0,O9))) -> 0 | K9: =IF(Eingaben!$B$14="","",IF(Eingaben!$D$6="Ja",2*MAX(0,Q9),MAX(0,Q9))) -> 0 | L9: =IF(Eingaben!$B$14="","",IF(Eingaben!$D$5>0,J9-K9,-I9*Eingaben!$D$9)) -> 1548.7457 | N9: =IF(Eingaben!$B$14="","",IF(Eingaben!$D$6="Ja",Eingaben!$F$6/2,Eingaben!$F$6)) -> 0 | O9: =IF(Eingaben!$B$14="","",IF(N9<=12348,0,IF(N9<=17799,(914.51*((N9-12348)/10000)+1400)*((N9-12348)/10000),IF(N9<=69878,(181.19*((N9-17799)/10000)+2397)*((N9-17799)/10000)+1025.38,IF(N9<=277825,0.42*N9-10637.32,0.45*N9-18971.07))))) -> 0 | P9: =IF(Eingaben!$B$14="","",IF(Eingaben!$D$6="Ja",MAX(0,Eingaben!$F$6+I9)/2,MAX(0,Eingaben!$F$6+I9))) -> 0 | Q9: =IF(Eingaben!$B$14="","",IF(P9<=12348,0,IF(P9<=17799,(914.51*((P9-12348)/10000)+1400)*((P9-12348)/10000),IF(P9<=69878,(181.19*((P9-17799)/10000)+2397)*((P9-17799)/10000)+1025.38,IF(P9<=277825,0.42*P9-10637.32,0.45*P9-18971.07))))) -> 0
A10: 1 | B10: =IF(Eingaben!$B$14="","",Cashflow!B10) -> Musterwohnung Berlin | C10: 6 | D10: =IF(Eingaben!$B$14="","",H9) -> 178560 | E10: =IF(Eingaben!$B$14="","",MIN(D10,MAX(0,IF(Eingaben!$S$14="Ja",D10*Eingaben!$T$14,Eingaben!$AD$14*Eingaben!$Q$14)))) -> 3968 | F10: =IF(Eingaben!$B$14="","",MIN(MAX(0,IF(AND(Eingaben!$U$14="Ja",6<=Eingaben!$W$14),Eingaben!$AD$14*Eingaben!$V$14,0)),MAX(0,D10-E10))) -> 0 | G10: =IF(Eingaben!$B$14="","",E10+F10) -> 3968 | H10: =IF(Eingaben!$B$14="","",D10-G10) -> 174592 | I10: =IF(Eingaben!$B$14="","",Cashflow!E10-Cashflow!G10-G10) -> -3543.7969 | J10: =IF(Eingaben!$B$14="","",IF(Eingaben!$D$6="Ja",2*MAX(0,O10),MAX(0,O10))) -> 0 | K10: =IF(Eingaben!$B$14="","",IF(Eingaben!$D$6="Ja",2*MAX(0,Q10),MAX(0,Q10))) -> 0 | L10: =IF(Eingaben!$B$14="","",IF(Eingaben!$D$5>0,J10-K10,-I10*Eingaben!$D$9)) -> 1417.5188 | N10: =IF(Eingaben!$B$14="","",IF(Eingaben!$D$6="Ja",Eingaben!$F$6/2,Eingaben!$F$6)) -> 0 | O10: =IF(Eingaben!$B$14="","",IF(N10<=12348,0,IF(N10<=17799,(914.51*((N10-12348)/10000)+1400)*((N10-12348)/10000),IF(N10<=69878,(181.19*((N10-17799)/10000)+2397)*((N10-17799)/10000)+1025.38,IF(N10<=277825,0.42*N10-10637.32,0.45*N10-18971.07))))) -> 0 | P10: =IF(Eingaben!$B$14="","",IF(Eingaben!$D$6="Ja",MAX(0,Eingaben!$F$6+I10)/2,MAX(0,Eingaben!$F$6+I10))) -> 0 | Q10: =IF(Eingaben!$B$14="","",IF(P10<=12348,0,IF(P10<=17799,(914.51*((P10-12348)/10000)+1400)*((P10-12348)/10000),IF(P10<=69878,(181.19*((P10-17799)/10000)+2397)*((P10-17799)/10000)+1025.38,IF(P10<=277825,0.42*P10-10637.32,0.45*P10-18971.07))))) -> 0
A11: 1 | B11: =IF(Eingaben!$B$14="","",Cashflow!B11) -> Musterwohnung Berlin | C11: 7 | D11: =IF(Eingaben!$B$14="","",H10) -> 174592 | E11: =IF(Eingaben!$B$14="","",MIN(D11,MAX(0,IF(Eingaben!$S$14="Ja",D11*Eingaben!$T$14,Eingaben!$AD$14*Eingaben!$Q$14)))) -> 3968 | F11: =IF(Eingaben!$B$14="","",MIN(MAX(0,IF(AND(Eingaben!$U$14="Ja",7<=Eingaben!$W$14),Eingaben!$AD$14*Eingaben!$V$14,0)),MAX(0,D11-E11))) -> 0 | G11: =IF(Eingaben!$B$14="","",E11+F11) -> 3968 | H11: =IF(Eingaben!$B$14="","",D11-G11) -> 170624 | I11: =IF(Eingaben!$B$14="","",Cashflow!E11-Cashflow!G11-G11) -> -3206.247 | J11: =IF(Eingaben!$B$14="","",IF(Eingaben!$D$6="Ja",2*MAX(0,O11),MAX(0,O11))) -> 0 | K11: =IF(Eingaben!$B$14="","",IF(Eingaben!$D$6="Ja",2*MAX(0,Q11),MAX(0,Q11))) -> 0 | L11: =IF(Eingaben!$B$14="","",IF(Eingaben!$D$5>0,J11-K11,-I11*Eingaben!$D$9)) -> 1282.4988 | N11: =IF(Eingaben!$B$14="","",IF(Eingaben!$D$6="Ja",Eingaben!$F$6/2,Eingaben!$F$6)) -> 0 | O11: =IF(Eingaben!$B$14="","",IF(N11<=12348,0,IF(N11<=17799,(914.51*((N11-12348)/10000)+1400)*((N11-12348)/10000),IF(N11<=69878,(181.19*((N11-17799)/10000)+2397)*((N11-17799)/10000)+1025.38,IF(N11<=277825,0.42*N11-10637.32,0.45*N11-18971.07))))) -> 0 | P11: =IF(Eingaben!$B$14="","",IF(Eingaben!$D$6="Ja",MAX(0,Eingaben!$F$6+I11)/2,MAX(0,Eingaben!$F$6+I11))) -> 0 | Q11: =IF(Eingaben!$B$14="","",IF(P11<=12348,0,IF(P11<=17799,(914.51*((P11-12348)/10000)+1400)*((P11-12348)/10000),IF(P11<=69878,(181.19*((P11-17799)/10000)+2397)*((P11-17799)/10000)+1025.38,IF(P11<=277825,0.42*P11-10637.32,0.45*P11-18971.07))))) -> 0
A12: 1 | B12: =IF(Eingaben!$B$14="","",Cashflow!B12) -> Musterwohnung Berlin | C12: 8 | D12: =IF(Eingaben!$B$14="","",H11) -> 170624 | E12: =IF(Eingaben!$B$14="","",MIN(D12,MAX(0,IF(Eingaben!$S$14="Ja",D12*Eingaben!$T$14,Eingaben!$AD$14*Eingaben!$Q$14)))) -> 3968 | F12: =IF(Eingaben!$B$14="","",MIN(MAX(0,IF(AND(Eingaben!$U$14="Ja",8<=Eingaben!$W$14),Eingaben!$AD$14*Eingaben!$V$14,0)),MAX(0,D12-E12))) -> 0 | G12: =IF(Eingaben!$B$14="","",E12+F12) -> 3968 | H12: =IF(Eingaben!$B$14="","",D12-G12) -> 166656 | I12: =IF(Eingaben!$B$14="","",Cashflow!E12-Cashflow!G12-G12) -> -2858.8999 | J12: =IF(Eingaben!$B$14="","",IF(Eingaben!$D$6="Ja",2*MAX(0,O12),MAX(0,O12))) -> 0 | K12: =IF(Eingaben!$B$14="","",IF(Eingaben!$D$6="Ja",2*MAX(0,Q12),MAX(0,Q12))) -> 0 | L12: =IF(Eingaben!$B$14="","",IF(Eingaben!$D$5>0,J12-K12,-I12*Eingaben!$D$9)) -> 1143.5599 | N12: =IF(Eingaben!$B$14="","",IF(Eingaben!$D$6="Ja",Eingaben!$F$6/2,Eingaben!$F$6)) -> 0 | O12: =IF(Eingaben!$B$14="","",IF(N12<=12348,0,IF(N12<=17799,(914.51*((N12-12348)/10000)+1400)*((N12-12348)/10000),IF(N12<=69878,(181.19*((N12-17799)/10000)+2397)*((N12-17799)/10000)+1025.38,IF(N12<=277825,0.42*N12-10637.32,0.45*N12-18971.07))))) -> 0 | P12: =IF(Eingaben!$B$14="","",IF(Eingaben!$D$6="Ja",MAX(0,Eingaben!$F$6+I12)/2,MAX(0,Eingaben!$F$6+I12))) -> 0 | Q12: =IF(Eingaben!$B$14="","",IF(P12<=12348,0,IF(P12<=17799,(914.51*((P12-12348)/10000)+1400)*((P12-12348)/10000),IF(P12<=69878,(181.19*((P12-17799)/10000)+2397)*((P12-17799)/10000)+1025.38,IF(P12<=277825,0.42*P12-10637.32,0.45*P12-18971.07))))) -> 0
A13: 1 | B13: =IF(Eingaben!$B$14="","",Cashflow!B13) -> Musterwohnung Berlin | C13: 9 | D13: =IF(Eingaben!$B$14="","",H12) -> 166656 | E13: =IF(Eingaben!$B$14="","",MIN(D13,MAX(0,IF(Eingaben!$S$14="Ja",D13*Eingaben!$T$14,Eingaben!$AD$14*Eingaben!$Q$14)))) -> 3968 | F13: =IF(Eingaben!$B$14="","",MIN(MAX(0,IF(AND(Eingaben!$U$14="Ja",9<=Eingaben!$W$14),Eingaben!$AD$14*Eingaben!$V$14,0)),MAX(0,D13-E13))) -> 0 | G13: =IF(Eingaben!$B$14="","",E13+F13) -> 3968 | H13: =IF(Eingaben!$B$14="","",D13-G13) -> 162688 | I13: =IF(Eingaben!$B$14="","",Cashflow!E13-Cashflow!G13-G13) -> -2501.429 | J13: =IF(Eingaben!$B$14="","",IF(Eingaben!$D$6="Ja",2*MAX(0,O13),MAX(0,O13))) -> 0 | K13: =IF(Eingaben!$B$14="","",IF(Eingaben!$D$6="Ja",2*MAX(0,Q13),MAX(0,Q13))) -> 0 | L13: =IF(Eingaben!$B$14="","",IF(Eingaben!$D$5>0,J13-K13,-I13*Eingaben!$D$9)) -> 1000.5716 | N13: =IF(Eingaben!$B$14="","",IF(Eingaben!$D$6="Ja",Eingaben!$F$6/2,Eingaben!$F$6)) -> 0 | O13: =IF(Eingaben!$B$14="","",IF(N13<=12348,0,IF(N13<=17799,(914.51*((N13-12348)/10000)+1400)*((N13-12348)/10000),IF(N13<=69878,(181.19*((N13-17799)/10000)+2397)*((N13-17799)/10000)+1025.38,IF(N13<=277825,0.42*N13-10637.32,0.45*N13-18971.07))))) -> 0 | P13: =IF(Eingaben!$B$14="","",IF(Eingaben!$D$6="Ja",MAX(0,Eingaben!$F$6+I13)/2,MAX(0,Eingaben!$F$6+I13))) -> 0 | Q13: =IF(Eingaben!$B$14="","",IF(P13<=12348,0,IF(P13<=17799,(914.51*((P13-12348)/10000)+1400)*((P13-12348)/10000),IF(P13<=69878,(181.19*((P13-17799)/10000)+2397)*((P13-17799)/10000)+1025.38,IF(P13<=277825,0.42*P13-10637.32,0.45*P13-18971.07))))) -> 0
A14: 1 | B14: =IF(Eingaben!$B$14="","",Cashflow!B14) -> Musterwohnung Berlin | C14: 10 | D14: =IF(Eingaben!$B$14="","",H13) -> 162688 | E14: =IF(Eingaben!$B$14="","",MIN(D14,MAX(0,IF(Eingaben!$S$14="Ja",D14*Eingaben!$T$14,Eingaben!$AD$14*Eingaben!$Q$14)))) -> 3968 | F14: =IF(Eingaben!$B$14="","",MIN(MAX(0,IF(AND(Eingaben!$U$14="Ja",10<=Eingaben!$W$14),Eingaben!$AD$14*Eingaben!$V$14,0)),MAX(0,D14-E14))) -> 0 | G14: =IF(Eingaben!$B$14="","",E14+F14) -> 3968 | H14: =IF(Eingaben!$B$14="","",D14-G14) -> 158720 | I14: =IF(Eingaben!$B$14="","",Cashflow!E14-Cashflow!G14-G14) -> -2133.4959 | J14: =IF(Eingaben!$B$14="","",IF(Eingaben!$D$6="Ja",2*MAX(0,O14),MAX(0,O14))) -> 0 | K14: =IF(Eingaben!$B$14="","",IF(Eingaben!$D$6="Ja",2*MAX(0,Q14),MAX(0,Q14))) -> 0 | L14: =IF(Eingaben!$B$14="","",IF(Eingaben!$D$5>0,J14-K14,-I14*Eingaben!$D$9)) -> 853.39838 | N14: =IF(Eingaben!$B$14="","",IF(Eingaben!$D$6="Ja",Eingaben!$F$6/2,Eingaben!$F$6)) -> 0 | O14: =IF(Eingaben!$B$14="","",IF(N14<=12348,0,IF(N14<=17799,(914.51*((N14-12348)/10000)+1400)*((N14-12348)/10000),IF(N14<=69878,(181.19*((N14-17799)/10000)+2397)*((N14-17799)/10000)+1025.38,IF(N14<=277825,0.42*N14-10637.32,0.45*N14-18971.07))))) -> 0 | P14: =IF(Eingaben!$B$14="","",IF(Eingaben!$D$6="Ja",MAX(0,Eingaben!$F$6+I14)/2,MAX(0,Eingaben!$F$6+I14))) -> 0 | Q14: =IF(Eingaben!$B$14="","",IF(P14<=12348,0,IF(P14<=17799,(914.51*((P14-12348)/10000)+1400)*((P14-12348)/10000),IF(P14<=69878,(181.19*((P14-17799)/10000)+2397)*((P14-17799)/10000)+1025.38,IF(P14<=277825,0.42*P14-10637.32,0.45*P14-18971.07))))) -> 0
A15: 2 | B15: =IF(Eingaben!$B$15="","",Cashflow!B15) | C15: 1 | D15: =IF(Eingaben!$B$15="","",Eingaben!$AD$15) | E15: =IF(Eingaben!$B$15="","",MIN(D15,MAX(0,IF(Eingaben!$S$15="Ja",D15*Eingaben!$T$15,Eingaben!$AD$15*Eingaben!$Q$15)))) | F15: =IF(Eingaben!$B$15="","",MIN(MAX(0,IF(AND(Eingaben!$U$15="Ja",1<=Eingaben!$W$15),Eingaben!$AD$15*Eingaben!$V$15,0)),MAX(0,D15-E15))) | G15: =IF(Eingaben!$B$15="","",E15+F15) | H15: =IF(Eingaben!$B$15="","",D15-G15) | I15: =IF(Eingaben!$B$15="","",Cashflow!E15-Cashflow!G15-G15) | J15: =IF(Eingaben!$B$15="","",IF(Eingaben!$D$6="Ja",2*MAX(0,O15),MAX(0,O15))) | K15: =IF(Eingaben!$B$15="","",IF(Eingaben!$D$6="Ja",2*MAX(0,Q15),MAX(0,Q15))) | L15: =IF(Eingaben!$B$15="","",IF(Eingaben!$D$5>0,J15-K15,-I15*Eingaben!$D$9)) | N15: =IF(Eingaben!$B$15="","",IF(Eingaben!$D$6="Ja",Eingaben!$F$6/2,Eingaben!$F$6)) | O15: =IF(Eingaben!$B$15="","",IF(N15<=12348,0,IF(N15<=17799,(914.51*((N15-12348)/10000)+1400)*((N15-12348)/10000),IF(N15<=69878,(181.19*((N15-17799)/10000)+2397)*((N15-17799)/10000)+1025.38,IF(N15<=277825,0.42*N15-10637.32,0.45*N15-18971.07))))) | P15: =IF(Eingaben!$B$15="","",IF(Eingaben!$D$6="Ja",MAX(0,Eingaben!$F$6+I15)/2,MAX(0,Eingaben!$F$6+I15))) | Q15: =IF(Eingaben!$B$15="","",IF(P15<=12348,0,IF(P15<=17799,(914.51*((P15-12348)/10000)+1400)*((P15-12348)/10000),IF(P15<=69878,(181.19*((P15-17799)/10000)+2397)*((P15-17799)/10000)+1025.38,IF(P15<=277825,0.42*P15-10637.32,0.45*P15-18971.07)))))
